[2025-05-31T20:56:36.132+0000] {taskinstance.py:1956} INFO - Dependencies all met for dep_context=non-requeueable deps ti=<TaskInstance: evaluate_and_train.train_model manual__2025-05-31T20:56:19.363082+00:00 [queued]>
[2025-05-31T20:56:36.189+0000] {taskinstance.py:1956} INFO - Dependencies all met for dep_context=requeueable deps ti=<TaskInstance: evaluate_and_train.train_model manual__2025-05-31T20:56:19.363082+00:00 [queued]>
[2025-05-31T20:56:36.189+0000] {taskinstance.py:2170} INFO - Starting attempt 1 of 2
[2025-05-31T20:56:36.255+0000] {taskinstance.py:2191} INFO - Executing <Task(PythonOperator): train_model> on 2025-05-31 20:56:19.363082+00:00
[2025-05-31T20:56:36.309+0000] {standard_task_runner.py:60} INFO - Started process 232 to run task
[2025-05-31T20:56:36.338+0000] {standard_task_runner.py:87} INFO - Running: ['***', 'tasks', 'run', 'evaluate_and_train', 'train_model', 'manual__2025-05-31T20:56:19.363082+00:00', '--job-id', '20', '--raw', '--subdir', 'DAGS_FOLDER/evaluate_and_train.py', '--cfg-path', '/tmp/tmpmd_za3sr']
[2025-05-31T20:56:36.361+0000] {standard_task_runner.py:88} INFO - Job 20: Subtask train_model
[2025-05-31T20:56:36.802+0000] {task_command.py:423} INFO - Running <TaskInstance: evaluate_and_train.train_model manual__2025-05-31T20:56:19.363082+00:00 [running]> on host 9c020e596300
[2025-05-31T20:56:37.144+0000] {taskinstance.py:2480} INFO - Exporting env vars: AIRFLOW_CTX_DAG_OWNER='***' AIRFLOW_CTX_DAG_ID='evaluate_and_train' AIRFLOW_CTX_TASK_ID='train_model' AIRFLOW_CTX_EXECUTION_DATE='2025-05-31T20:56:19.363082+00:00' AIRFLOW_CTX_TRY_NUMBER='1' AIRFLOW_CTX_DAG_RUN_ID='manual__2025-05-31T20:56:19.363082+00:00'
[2025-05-31T20:56:37.225+0000] {taskinstance.py:2698} ERROR - Task failed with exception
Traceback (most recent call last):
  File "/home/airflow/.local/lib/python3.8/site-packages/airflow/models/taskinstance.py", line 433, in _execute_task
    result = execute_callable(context=context, **execute_callable_kwargs)
  File "/home/airflow/.local/lib/python3.8/site-packages/airflow/operators/python.py", line 199, in execute
    return_value = self.execute_callable()
  File "/home/airflow/.local/lib/python3.8/site-packages/airflow/operators/python.py", line 216, in execute_callable
    return self.python_callable(*self.op_args, **self.op_kwargs)
  File "/opt/airflow/dags/evaluate_and_train.py", line 63, in train_model
    raise ValueError("La columna 'price' no está disponible para entrenamiento.")
ValueError: La columna 'price' no está disponible para entrenamiento.
[2025-05-31T20:56:37.272+0000] {taskinstance.py:1138} INFO - Marking task as UP_FOR_RETRY. dag_id=evaluate_and_train, task_id=train_model, execution_date=20250531T205619, start_date=20250531T205636, end_date=20250531T205637
[2025-05-31T20:56:37.329+0000] {standard_task_runner.py:107} ERROR - Failed to execute job 20 for task train_model (La columna 'price' no está disponible para entrenamiento.; 232)
[2025-05-31T20:56:37.394+0000] {local_task_job_runner.py:234} INFO - Task exited with return code 1
[2025-05-31T20:56:37.497+0000] {taskinstance.py:3280} INFO - 0 downstream tasks scheduled from follow-on schedule check
