[2025-06-01T14:46:34.024+0000] {taskinstance.py:1956} INFO - Dependencies all met for dep_context=non-requeueable deps ti=<TaskInstance: evaluate_and_train.should_train_model manual__2025-06-01T14:45:25.912596+00:00 [queued]>
[2025-06-01T14:46:34.047+0000] {taskinstance.py:1956} INFO - Dependencies all met for dep_context=requeueable deps ti=<TaskInstance: evaluate_and_train.should_train_model manual__2025-06-01T14:45:25.912596+00:00 [queued]>
[2025-06-01T14:46:34.048+0000] {taskinstance.py:2170} INFO - Starting attempt 2 of 2
[2025-06-01T14:46:34.083+0000] {taskinstance.py:2191} INFO - Executing <Task(PythonOperator): should_train_model> on 2025-06-01 14:45:25.912596+00:00
[2025-06-01T14:46:34.108+0000] {standard_task_runner.py:60} INFO - Started process 28679 to run task
[2025-06-01T14:46:34.120+0000] {standard_task_runner.py:87} INFO - Running: ['***', 'tasks', 'run', 'evaluate_and_train', 'should_train_model', 'manual__2025-06-01T14:45:25.912596+00:00', '--job-id', '94', '--raw', '--subdir', 'DAGS_FOLDER/evaluate_and_train.py', '--cfg-path', '/tmp/tmpjlcmjsfy']
[2025-06-01T14:46:34.127+0000] {standard_task_runner.py:88} INFO - Job 94: Subtask should_train_model
[2025-06-01T14:46:34.301+0000] {task_command.py:423} INFO - Running <TaskInstance: evaluate_and_train.should_train_model manual__2025-06-01T14:45:25.912596+00:00 [running]> on host 9c020e596300
[2025-06-01T14:46:34.589+0000] {taskinstance.py:2480} INFO - Exporting env vars: AIRFLOW_CTX_DAG_OWNER='***' AIRFLOW_CTX_DAG_ID='evaluate_and_train' AIRFLOW_CTX_TASK_ID='should_train_model' AIRFLOW_CTX_EXECUTION_DATE='2025-06-01T14:45:25.912596+00:00' AIRFLOW_CTX_TRY_NUMBER='2' AIRFLOW_CTX_DAG_RUN_ID='manual__2025-06-01T14:45:25.912596+00:00'
[2025-06-01T14:46:34.633+0000] {taskinstance.py:2698} ERROR - Task failed with exception
Traceback (most recent call last):
  File "/home/airflow/.local/lib/python3.8/site-packages/sqlalchemy/engine/base.py", line 1910, in _execute_context
    self.dialect.do_execute(
  File "/home/airflow/.local/lib/python3.8/site-packages/sqlalchemy/engine/default.py", line 736, in do_execute
    cursor.execute(statement, parameters)
psycopg2.errors.UndefinedTable: relation "clean_data" does not exist
LINE 1: SELECT * FROM clean_data
                      ^


The above exception was the direct cause of the following exception:

Traceback (most recent call last):
  File "/home/airflow/.local/lib/python3.8/site-packages/airflow/models/taskinstance.py", line 433, in _execute_task
    result = execute_callable(context=context, **execute_callable_kwargs)
  File "/home/airflow/.local/lib/python3.8/site-packages/airflow/operators/python.py", line 199, in execute
    return_value = self.execute_callable()
  File "/home/airflow/.local/lib/python3.8/site-packages/airflow/operators/python.py", line 216, in execute_callable
    return self.python_callable(*self.op_args, **self.op_kwargs)
  File "/opt/airflow/dags/evaluate_and_train.py", line 37, in should_train_model
    df = pd.read_sql(f"SELECT * FROM {TABLE_CLEAN}", engine)
  File "/home/airflow/.local/lib/python3.8/site-packages/pandas/io/sql.py", line 663, in read_sql
    return pandas_sql.read_query(
  File "/home/airflow/.local/lib/python3.8/site-packages/pandas/io/sql.py", line 1738, in read_query
    result = self.execute(sql, params)
  File "/home/airflow/.local/lib/python3.8/site-packages/pandas/io/sql.py", line 1562, in execute
    return self.con.exec_driver_sql(sql, *args)
  File "/home/airflow/.local/lib/python3.8/site-packages/sqlalchemy/engine/base.py", line 1770, in exec_driver_sql
    return self._exec_driver_sql(
  File "/home/airflow/.local/lib/python3.8/site-packages/sqlalchemy/engine/base.py", line 1674, in _exec_driver_sql
    ret = self._execute_context(
  File "/home/airflow/.local/lib/python3.8/site-packages/sqlalchemy/engine/base.py", line 1953, in _execute_context
    self._handle_dbapi_exception(
  File "/home/airflow/.local/lib/python3.8/site-packages/sqlalchemy/engine/base.py", line 2134, in _handle_dbapi_exception
    util.raise_(
  File "/home/airflow/.local/lib/python3.8/site-packages/sqlalchemy/util/compat.py", line 211, in raise_
    raise exception
  File "/home/airflow/.local/lib/python3.8/site-packages/sqlalchemy/engine/base.py", line 1910, in _execute_context
    self.dialect.do_execute(
  File "/home/airflow/.local/lib/python3.8/site-packages/sqlalchemy/engine/default.py", line 736, in do_execute
    cursor.execute(statement, parameters)
sqlalchemy.exc.ProgrammingError: (psycopg2.errors.UndefinedTable) relation "clean_data" does not exist
LINE 1: SELECT * FROM clean_data
                      ^

[SQL: SELECT * FROM clean_data]
(Background on this error at: https://sqlalche.me/e/14/f405)
[2025-06-01T14:46:34.666+0000] {taskinstance.py:1138} INFO - Marking task as FAILED. dag_id=evaluate_and_train, task_id=should_train_model, execution_date=20250601T144525, start_date=20250601T144634, end_date=20250601T144634
[2025-06-01T14:46:34.688+0000] {standard_task_runner.py:107} ERROR - Failed to execute job 94 for task should_train_model ((psycopg2.errors.UndefinedTable) relation "clean_data" does not exist
LINE 1: SELECT * FROM clean_data
                      ^

[SQL: SELECT * FROM clean_data]
(Background on this error at: https://sqlalche.me/e/14/f405); 28679)
[2025-06-01T14:46:34.741+0000] {local_task_job_runner.py:234} INFO - Task exited with return code 1
[2025-06-01T14:46:34.798+0000] {taskinstance.py:3280} INFO - 0 downstream tasks scheduled from follow-on schedule check
