[2025-05-31T20:38:50.919+0000] {taskinstance.py:1956} INFO - Dependencies all met for dep_context=non-requeueable deps ti=<TaskInstance: get_ingest_preprocess.preprocess_data manual__2025-05-31T20:38:43.455609+00:00 [queued]>
[2025-05-31T20:38:50.953+0000] {taskinstance.py:1956} INFO - Dependencies all met for dep_context=requeueable deps ti=<TaskInstance: get_ingest_preprocess.preprocess_data manual__2025-05-31T20:38:43.455609+00:00 [queued]>
[2025-05-31T20:38:50.954+0000] {taskinstance.py:2170} INFO - Starting attempt 1 of 2
[2025-05-31T20:38:50.990+0000] {taskinstance.py:2191} INFO - Executing <Task(PythonOperator): preprocess_data> on 2025-05-31 20:38:43.455609+00:00
[2025-05-31T20:38:51.010+0000] {standard_task_runner.py:60} INFO - Started process 219 to run task
[2025-05-31T20:38:51.025+0000] {standard_task_runner.py:87} INFO - Running: ['***', 'tasks', 'run', 'get_ingest_preprocess', 'preprocess_data', 'manual__2025-05-31T20:38:43.455609+00:00', '--job-id', '9', '--raw', '--subdir', 'DAGS_FOLDER/get_ingest_preprocess.py', '--cfg-path', '/tmp/tmpl07m36ci']
[2025-05-31T20:38:51.032+0000] {standard_task_runner.py:88} INFO - Job 9: Subtask preprocess_data
[2025-05-31T20:38:51.227+0000] {task_command.py:423} INFO - Running <TaskInstance: get_ingest_preprocess.preprocess_data manual__2025-05-31T20:38:43.455609+00:00 [running]> on host 9c020e596300
[2025-05-31T20:38:51.545+0000] {taskinstance.py:2480} INFO - Exporting env vars: AIRFLOW_CTX_DAG_OWNER='***' AIRFLOW_CTX_DAG_ID='get_ingest_preprocess' AIRFLOW_CTX_TASK_ID='preprocess_data' AIRFLOW_CTX_EXECUTION_DATE='2025-05-31T20:38:43.455609+00:00' AIRFLOW_CTX_TRY_NUMBER='1' AIRFLOW_CTX_DAG_RUN_ID='manual__2025-05-31T20:38:43.455609+00:00'
[2025-05-31T20:38:51.725+0000] {taskinstance.py:2698} ERROR - Task failed with exception
Traceback (most recent call last):
  File "/home/airflow/.local/lib/python3.8/site-packages/airflow/models/taskinstance.py", line 433, in _execute_task
    result = execute_callable(context=context, **execute_callable_kwargs)
  File "/home/airflow/.local/lib/python3.8/site-packages/airflow/operators/python.py", line 199, in execute
    return_value = self.execute_callable()
  File "/home/airflow/.local/lib/python3.8/site-packages/airflow/operators/python.py", line 216, in execute_callable
    return self.python_callable(*self.op_args, **self.op_kwargs)
  File "/opt/airflow/dags/get_ingest_preprocess.py", line 62, in preprocess_data
    df = df.dropna(subset=["price", "bed", "bath", "house size", "acre lot"])
  File "/home/airflow/.local/lib/python3.8/site-packages/pandas/core/frame.py", line 6407, in dropna
    raise KeyError(np.array(subset)[check].tolist())
KeyError: ['price', 'bed', 'bath', 'house size', 'acre lot']
[2025-05-31T20:38:51.802+0000] {taskinstance.py:1138} INFO - Marking task as UP_FOR_RETRY. dag_id=get_ingest_preprocess, task_id=preprocess_data, execution_date=20250531T203843, start_date=20250531T203850, end_date=20250531T203851
[2025-05-31T20:38:51.843+0000] {standard_task_runner.py:107} ERROR - Failed to execute job 9 for task preprocess_data (['price', 'bed', 'bath', 'house size', 'acre lot']; 219)
[2025-05-31T20:38:51.892+0000] {local_task_job_runner.py:234} INFO - Task exited with return code 1
[2025-05-31T20:38:51.965+0000] {taskinstance.py:3280} INFO - 0 downstream tasks scheduled from follow-on schedule check
