[2025-05-31T20:29:01.287+0000] {taskinstance.py:1956} INFO - Dependencies all met for dep_context=non-requeueable deps ti=<TaskInstance: get_ingest_preprocess.get_data_from_api scheduled__2024-01-01T00:00:00+00:00 [queued]>
[2025-05-31T20:29:01.322+0000] {taskinstance.py:1956} INFO - Dependencies all met for dep_context=requeueable deps ti=<TaskInstance: get_ingest_preprocess.get_data_from_api scheduled__2024-01-01T00:00:00+00:00 [queued]>
[2025-05-31T20:29:01.322+0000] {taskinstance.py:2170} INFO - Starting attempt 1 of 2
[2025-05-31T20:29:01.356+0000] {taskinstance.py:2191} INFO - Executing <Task(PythonOperator): get_data_from_api> on 2024-01-01 00:00:00+00:00
[2025-05-31T20:29:01.394+0000] {standard_task_runner.py:60} INFO - Started process 203 to run task
[2025-05-31T20:29:01.410+0000] {standard_task_runner.py:87} INFO - Running: ['***', 'tasks', 'run', 'get_ingest_preprocess', 'get_data_from_api', 'scheduled__2024-01-01T00:00:00+00:00', '--job-id', '3', '--raw', '--subdir', 'DAGS_FOLDER/get_ingest_preprocess.py', '--cfg-path', '/tmp/tmpvj_qzsl5']
[2025-05-31T20:29:01.417+0000] {standard_task_runner.py:88} INFO - Job 3: Subtask get_data_from_api
[2025-05-31T20:29:01.643+0000] {task_command.py:423} INFO - Running <TaskInstance: get_ingest_preprocess.get_data_from_api scheduled__2024-01-01T00:00:00+00:00 [running]> on host 9c020e596300
[2025-05-31T20:29:01.956+0000] {taskinstance.py:2480} INFO - Exporting env vars: AIRFLOW_CTX_DAG_OWNER='***' AIRFLOW_CTX_DAG_ID='get_ingest_preprocess' AIRFLOW_CTX_TASK_ID='get_data_from_api' AIRFLOW_CTX_EXECUTION_DATE='2024-01-01T00:00:00+00:00' AIRFLOW_CTX_TRY_NUMBER='1' AIRFLOW_CTX_DAG_RUN_ID='scheduled__2024-01-01T00:00:00+00:00'
[2025-05-31T20:29:01.991+0000] {taskinstance.py:2698} ERROR - Task failed with exception
Traceback (most recent call last):
  File "/home/airflow/.local/lib/python3.8/site-packages/airflow/models/taskinstance.py", line 433, in _execute_task
    result = execute_callable(context=context, **execute_callable_kwargs)
  File "/home/airflow/.local/lib/python3.8/site-packages/airflow/operators/python.py", line 199, in execute
    return_value = self.execute_callable()
  File "/home/airflow/.local/lib/python3.8/site-packages/airflow/operators/python.py", line 216, in execute_callable
    return self.python_callable(*self.op_args, **self.op_kwargs)
  File "/opt/airflow/dags/get_ingest_preprocess.py", line 46, in get_data_from_api
    df = pd.DataFrame(data)
  File "/home/airflow/.local/lib/python3.8/site-packages/pandas/core/frame.py", line 709, in __init__
    mgr = dict_to_mgr(data, index, columns, dtype=dtype, copy=copy, typ=manager)
  File "/home/airflow/.local/lib/python3.8/site-packages/pandas/core/internals/construction.py", line 481, in dict_to_mgr
    return arrays_to_mgr(arrays, columns, index, dtype=dtype, typ=typ, consolidate=copy)
  File "/home/airflow/.local/lib/python3.8/site-packages/pandas/core/internals/construction.py", line 115, in arrays_to_mgr
    index = _extract_index(arrays)
  File "/home/airflow/.local/lib/python3.8/site-packages/pandas/core/internals/construction.py", line 645, in _extract_index
    raise ValueError("If using all scalar values, you must pass an index")
ValueError: If using all scalar values, you must pass an index
[2025-05-31T20:29:02.036+0000] {taskinstance.py:1138} INFO - Marking task as UP_FOR_RETRY. dag_id=get_ingest_preprocess, task_id=get_data_from_api, execution_date=20240101T000000, start_date=20250531T202901, end_date=20250531T202902
[2025-05-31T20:29:02.075+0000] {standard_task_runner.py:107} ERROR - Failed to execute job 3 for task get_data_from_api (If using all scalar values, you must pass an index; 203)
[2025-05-31T20:29:02.122+0000] {local_task_job_runner.py:234} INFO - Task exited with return code 1
[2025-05-31T20:29:02.217+0000] {taskinstance.py:3280} INFO - 0 downstream tasks scheduled from follow-on schedule check
