[2025-05-31T20:57:39.870+0000] {taskinstance.py:1956} INFO - Dependencies all met for dep_context=non-requeueable deps ti=<TaskInstance: evaluate_and_train.train_model scheduled__2024-01-01T00:00:00+00:00 [queued]>
[2025-05-31T20:57:39.901+0000] {taskinstance.py:1956} INFO - Dependencies all met for dep_context=requeueable deps ti=<TaskInstance: evaluate_and_train.train_model scheduled__2024-01-01T00:00:00+00:00 [queued]>
[2025-05-31T20:57:39.902+0000] {taskinstance.py:2170} INFO - Starting attempt 2 of 2
[2025-05-31T20:57:39.934+0000] {taskinstance.py:2191} INFO - Executing <Task(PythonOperator): train_model> on 2024-01-01 00:00:00+00:00
[2025-05-31T20:57:39.963+0000] {standard_task_runner.py:60} INFO - Started process 268 to run task
[2025-05-31T20:57:39.976+0000] {standard_task_runner.py:87} INFO - Running: ['***', 'tasks', 'run', 'evaluate_and_train', 'train_model', 'scheduled__2024-01-01T00:00:00+00:00', '--job-id', '21', '--raw', '--subdir', 'DAGS_FOLDER/evaluate_and_train.py', '--cfg-path', '/tmp/tmp92vxt4jm']
[2025-05-31T20:57:39.984+0000] {standard_task_runner.py:88} INFO - Job 21: Subtask train_model
[2025-05-31T20:57:40.212+0000] {task_command.py:423} INFO - Running <TaskInstance: evaluate_and_train.train_model scheduled__2024-01-01T00:00:00+00:00 [running]> on host 9c020e596300
[2025-05-31T20:57:40.847+0000] {taskinstance.py:2480} INFO - Exporting env vars: AIRFLOW_CTX_DAG_OWNER='***' AIRFLOW_CTX_DAG_ID='evaluate_and_train' AIRFLOW_CTX_TASK_ID='train_model' AIRFLOW_CTX_EXECUTION_DATE='2024-01-01T00:00:00+00:00' AIRFLOW_CTX_TRY_NUMBER='2' AIRFLOW_CTX_DAG_RUN_ID='scheduled__2024-01-01T00:00:00+00:00'
[2025-05-31T20:57:40.923+0000] {taskinstance.py:2698} ERROR - Task failed with exception
Traceback (most recent call last):
  File "/home/airflow/.local/lib/python3.8/site-packages/airflow/models/taskinstance.py", line 433, in _execute_task
    result = execute_callable(context=context, **execute_callable_kwargs)
  File "/home/airflow/.local/lib/python3.8/site-packages/airflow/operators/python.py", line 199, in execute
    return_value = self.execute_callable()
  File "/home/airflow/.local/lib/python3.8/site-packages/airflow/operators/python.py", line 216, in execute_callable
    return self.python_callable(*self.op_args, **self.op_kwargs)
  File "/opt/airflow/dags/evaluate_and_train.py", line 63, in train_model
    raise ValueError("La columna 'price' no está disponible para entrenamiento.")
ValueError: La columna 'price' no está disponible para entrenamiento.
[2025-05-31T20:57:40.960+0000] {taskinstance.py:1138} INFO - Marking task as FAILED. dag_id=evaluate_and_train, task_id=train_model, execution_date=20240101T000000, start_date=20250531T205739, end_date=20250531T205740
[2025-05-31T20:57:40.993+0000] {standard_task_runner.py:107} ERROR - Failed to execute job 21 for task train_model (La columna 'price' no está disponible para entrenamiento.; 268)
[2025-05-31T20:57:41.101+0000] {local_task_job_runner.py:234} INFO - Task exited with return code 1
[2025-05-31T20:57:41.310+0000] {taskinstance.py:3280} INFO - 0 downstream tasks scheduled from follow-on schedule check
