[2025-05-31T20:56:34.973+0000] {taskinstance.py:1956} INFO - Dependencies all met for dep_context=non-requeueable deps ti=<TaskInstance: evaluate_and_train.train_model scheduled__2024-01-01T00:00:00+00:00 [queued]>
[2025-05-31T20:56:35.021+0000] {taskinstance.py:1956} INFO - Dependencies all met for dep_context=requeueable deps ti=<TaskInstance: evaluate_and_train.train_model scheduled__2024-01-01T00:00:00+00:00 [queued]>
[2025-05-31T20:56:35.023+0000] {taskinstance.py:2170} INFO - Starting attempt 1 of 2
[2025-05-31T20:56:35.104+0000] {taskinstance.py:2191} INFO - Executing <Task(PythonOperator): train_model> on 2024-01-01 00:00:00+00:00
[2025-05-31T20:56:35.226+0000] {standard_task_runner.py:60} INFO - Started process 230 to run task
[2025-05-31T20:56:35.270+0000] {standard_task_runner.py:87} INFO - Running: ['***', 'tasks', 'run', 'evaluate_and_train', 'train_model', 'scheduled__2024-01-01T00:00:00+00:00', '--job-id', '18', '--raw', '--subdir', 'DAGS_FOLDER/evaluate_and_train.py', '--cfg-path', '/tmp/tmp9y6k11c_']
[2025-05-31T20:56:35.291+0000] {standard_task_runner.py:88} INFO - Job 18: Subtask train_model
[2025-05-31T20:56:35.725+0000] {task_command.py:423} INFO - Running <TaskInstance: evaluate_and_train.train_model scheduled__2024-01-01T00:00:00+00:00 [running]> on host 9c020e596300
[2025-05-31T20:56:36.459+0000] {taskinstance.py:2480} INFO - Exporting env vars: AIRFLOW_CTX_DAG_OWNER='***' AIRFLOW_CTX_DAG_ID='evaluate_and_train' AIRFLOW_CTX_TASK_ID='train_model' AIRFLOW_CTX_EXECUTION_DATE='2024-01-01T00:00:00+00:00' AIRFLOW_CTX_TRY_NUMBER='1' AIRFLOW_CTX_DAG_RUN_ID='scheduled__2024-01-01T00:00:00+00:00'
[2025-05-31T20:56:36.627+0000] {taskinstance.py:2698} ERROR - Task failed with exception
Traceback (most recent call last):
  File "/home/airflow/.local/lib/python3.8/site-packages/airflow/models/taskinstance.py", line 433, in _execute_task
    result = execute_callable(context=context, **execute_callable_kwargs)
  File "/home/airflow/.local/lib/python3.8/site-packages/airflow/operators/python.py", line 199, in execute
    return_value = self.execute_callable()
  File "/home/airflow/.local/lib/python3.8/site-packages/airflow/operators/python.py", line 216, in execute_callable
    return self.python_callable(*self.op_args, **self.op_kwargs)
  File "/opt/airflow/dags/evaluate_and_train.py", line 63, in train_model
    raise ValueError("La columna 'price' no está disponible para entrenamiento.")
ValueError: La columna 'price' no está disponible para entrenamiento.
[2025-05-31T20:56:36.679+0000] {taskinstance.py:1138} INFO - Marking task as UP_FOR_RETRY. dag_id=evaluate_and_train, task_id=train_model, execution_date=20240101T000000, start_date=20250531T205634, end_date=20250531T205636
[2025-05-31T20:56:36.727+0000] {standard_task_runner.py:107} ERROR - Failed to execute job 18 for task train_model (La columna 'price' no está disponible para entrenamiento.; 230)
[2025-05-31T20:56:36.832+0000] {local_task_job_runner.py:234} INFO - Task exited with return code 1
[2025-05-31T20:56:37.006+0000] {taskinstance.py:3280} INFO - 0 downstream tasks scheduled from follow-on schedule check
